} catch (...) {
        cout << "Some other exception caught" << endl;